[2025-05-01 17:35:32,878] 20 root - ERROR - Failed to read data
Traceback (most recent call last):
  File "D:\campusx_dsmp2\9. MLOps revisited\cars24_mlops_project\src\components\data_transformation.py", line 15, in read_data
    train_df = pd.read_csv(train_path)
  File "C:\Users\iampr\AppData\Local\Programs\Python\Python38\lib\site-packages\pandas\io\parsers\readers.py", line 912, in read_csv
    return _read(filepath_or_buffer, kwds)
  File "C:\Users\iampr\AppData\Local\Programs\Python\Python38\lib\site-packages\pandas\io\parsers\readers.py", line 577, in _read
    parser = TextFileReader(filepath_or_buffer, **kwds)
  File "C:\Users\iampr\AppData\Local\Programs\Python\Python38\lib\site-packages\pandas\io\parsers\readers.py", line 1407, in __init__
    self._engine = self._make_engine(f, self.engine)
  File "C:\Users\iampr\AppData\Local\Programs\Python\Python38\lib\site-packages\pandas\io\parsers\readers.py", line 1661, in _make_engine
    self.handles = get_handle(
  File "C:\Users\iampr\AppData\Local\Programs\Python\Python38\lib\site-packages\pandas\io\common.py", line 859, in get_handle
    handle = open(
FileNotFoundError: [Errno 2] No such file or directory: 'D:\\campusx_dsmp2\\9. MLOps revisited\\cars24_mlops_project\\artifacts\\data_ingestion\\train.csv'
